[2024-06-20T11:37:49.275+0000] {local_task_job_runner.py:120} INFO - ::group::Pre task execution logs
[2024-06-20T11:37:49.293+0000] {taskinstance.py:2076} INFO - Dependencies all met for dep_context=non-requeueable deps ti=<TaskInstance: etl_to_analytics_database_v3.load_data manual__2024-06-20T11:37:46.262069+00:00 [queued]>
[2024-06-20T11:37:49.299+0000] {taskinstance.py:2076} INFO - Dependencies all met for dep_context=requeueable deps ti=<TaskInstance: etl_to_analytics_database_v3.load_data manual__2024-06-20T11:37:46.262069+00:00 [queued]>
[2024-06-20T11:37:49.300+0000] {taskinstance.py:2306} INFO - Starting attempt 1 of 1
[2024-06-20T11:37:49.309+0000] {taskinstance.py:2330} INFO - Executing <Task(PythonOperator): load_data> on 2024-06-20 11:37:46.262069+00:00
[2024-06-20T11:37:49.314+0000] {warnings.py:112} WARNING - /home/***/.local/lib/python3.12/site-packages/***/task/task_runner/standard_task_runner.py:61: DeprecationWarning: This process (pid=18295) is multi-threaded, use of fork() may lead to deadlocks in the child.
  pid = os.fork()

[2024-06-20T11:37:49.315+0000] {standard_task_runner.py:63} INFO - Started process 18296 to run task
[2024-06-20T11:37:49.315+0000] {standard_task_runner.py:90} INFO - Running: ['***', 'tasks', 'run', 'etl_to_analytics_database_v3', 'load_data', 'manual__2024-06-20T11:37:46.262069+00:00', '--job-id', '796', '--raw', '--subdir', 'DAGS_FOLDER/batch-processing_dag.py', '--cfg-path', '/tmp/tmps65p5z7n']
[2024-06-20T11:37:49.316+0000] {standard_task_runner.py:91} INFO - Job 796: Subtask load_data
[2024-06-20T11:37:49.346+0000] {task_command.py:426} INFO - Running <TaskInstance: etl_to_analytics_database_v3.load_data manual__2024-06-20T11:37:46.262069+00:00 [running]> on host 195daacf7793
[2024-06-20T11:37:49.402+0000] {taskinstance.py:2648} INFO - Exporting env vars: AIRFLOW_CTX_DAG_OWNER='***' AIRFLOW_CTX_DAG_ID='etl_to_analytics_database_v3' AIRFLOW_CTX_TASK_ID='load_data' AIRFLOW_CTX_EXECUTION_DATE='2024-06-20T11:37:46.262069+00:00' AIRFLOW_CTX_TRY_NUMBER='1' AIRFLOW_CTX_DAG_RUN_ID='manual__2024-06-20T11:37:46.262069+00:00'
[2024-06-20T11:37:49.403+0000] {taskinstance.py:430} INFO - ::endgroup::
[2024-06-20T11:37:49.432+0000] {base.py:84} INFO - Using connection ID 'analytics_localhost' for task execution.
[2024-06-20T11:37:49.445+0000] {taskinstance.py:441} INFO - ::group::Post task execution logs
[2024-06-20T11:37:49.446+0000] {taskinstance.py:2905} ERROR - Task failed with exception
Traceback (most recent call last):
  File "/home/airflow/.local/lib/python3.12/site-packages/MySQLdb/cursors.py", line 200, in _mogrify
    query = query % args
            ~~~~~~^~~~~~
TypeError: %d format: a real number is required, not bytes

During handling of the above exception, another exception occurred:

Traceback (most recent call last):
  File "/home/airflow/.local/lib/python3.12/site-packages/airflow/models/taskinstance.py", line 465, in _execute_task
    result = _execute_callable(context=context, **execute_callable_kwargs)
             ^^^^^^^^^^^^^^^^^^^^^^^^^^^^^^^^^^^^^^^^^^^^^^^^^^^^^^^^^^^^^
  File "/home/airflow/.local/lib/python3.12/site-packages/airflow/models/taskinstance.py", line 432, in _execute_callable
    return execute_callable(context=context, **execute_callable_kwargs)
           ^^^^^^^^^^^^^^^^^^^^^^^^^^^^^^^^^^^^^^^^^^^^^^^^^^^^^^^^^^^^
  File "/home/airflow/.local/lib/python3.12/site-packages/airflow/models/baseoperator.py", line 401, in wrapper
    return func(self, *args, **kwargs)
           ^^^^^^^^^^^^^^^^^^^^^^^^^^^
  File "/home/airflow/.local/lib/python3.12/site-packages/airflow/operators/python.py", line 235, in execute
    return_value = self.execute_callable()
                   ^^^^^^^^^^^^^^^^^^^^^^^
  File "/home/airflow/.local/lib/python3.12/site-packages/airflow/operators/python.py", line 252, in execute_callable
    return self.python_callable(*self.op_args, **self.op_kwargs)
           ^^^^^^^^^^^^^^^^^^^^^^^^^^^^^^^^^^^^^^^^^^^^^^^^^^^^^
  File "/opt/airflow/dags/batch-processing_dag.py", line 106, in load_data
    cursor.execute("""
  File "/home/airflow/.local/lib/python3.12/site-packages/MySQLdb/cursors.py", line 176, in execute
    mogrified_query = self._mogrify(query, args)
                      ^^^^^^^^^^^^^^^^^^^^^^^^^^
  File "/home/airflow/.local/lib/python3.12/site-packages/MySQLdb/cursors.py", line 202, in _mogrify
    raise ProgrammingError(str(m))
MySQLdb.ProgrammingError: %d format: a real number is required, not bytes
[2024-06-20T11:37:49.453+0000] {taskinstance.py:1206} INFO - Marking task as FAILED. dag_id=etl_to_analytics_database_v3, task_id=load_data, run_id=manual__2024-06-20T11:37:46.262069+00:00, execution_date=20240620T113746, start_date=20240620T113749, end_date=20240620T113749
[2024-06-20T11:37:49.461+0000] {standard_task_runner.py:110} ERROR - Failed to execute job 796 for task load_data (%d format: a real number is required, not bytes; 18296)
[2024-06-20T11:37:49.489+0000] {local_task_job_runner.py:240} INFO - Task exited with return code 1
[2024-06-20T11:37:49.499+0000] {taskinstance.py:3503} INFO - 0 downstream tasks scheduled from follow-on schedule check
[2024-06-20T11:37:49.501+0000] {local_task_job_runner.py:222} INFO - ::endgroup::
