[2024-06-20T11:42:41.162+0000] {local_task_job_runner.py:120} INFO - ::group::Pre task execution logs
[2024-06-20T11:42:41.178+0000] {taskinstance.py:2076} INFO - Dependencies all met for dep_context=non-requeueable deps ti=<TaskInstance: etl_to_analytics_database_v3.load_data manual__2024-06-20T11:42:37.933901+00:00 [queued]>
[2024-06-20T11:42:41.184+0000] {taskinstance.py:2076} INFO - Dependencies all met for dep_context=requeueable deps ti=<TaskInstance: etl_to_analytics_database_v3.load_data manual__2024-06-20T11:42:37.933901+00:00 [queued]>
[2024-06-20T11:42:41.185+0000] {taskinstance.py:2306} INFO - Starting attempt 1 of 1
[2024-06-20T11:42:41.194+0000] {taskinstance.py:2330} INFO - Executing <Task(PythonOperator): load_data> on 2024-06-20 11:42:37.933901+00:00
[2024-06-20T11:42:41.199+0000] {warnings.py:112} WARNING - /home/***/.local/lib/python3.12/site-packages/***/task/task_runner/standard_task_runner.py:61: DeprecationWarning: This process (pid=18370) is multi-threaded, use of fork() may lead to deadlocks in the child.
  pid = os.fork()

[2024-06-20T11:42:41.200+0000] {standard_task_runner.py:63} INFO - Started process 18371 to run task
[2024-06-20T11:42:41.200+0000] {standard_task_runner.py:90} INFO - Running: ['***', 'tasks', 'run', 'etl_to_analytics_database_v3', 'load_data', 'manual__2024-06-20T11:42:37.933901+00:00', '--job-id', '802', '--raw', '--subdir', 'DAGS_FOLDER/batch-processing_dag.py', '--cfg-path', '/tmp/tmpobssco43']
[2024-06-20T11:42:41.201+0000] {standard_task_runner.py:91} INFO - Job 802: Subtask load_data
[2024-06-20T11:42:41.233+0000] {task_command.py:426} INFO - Running <TaskInstance: etl_to_analytics_database_v3.load_data manual__2024-06-20T11:42:37.933901+00:00 [running]> on host 195daacf7793
[2024-06-20T11:42:41.328+0000] {taskinstance.py:2648} INFO - Exporting env vars: AIRFLOW_CTX_DAG_OWNER='***' AIRFLOW_CTX_DAG_ID='etl_to_analytics_database_v3' AIRFLOW_CTX_TASK_ID='load_data' AIRFLOW_CTX_EXECUTION_DATE='2024-06-20T11:42:37.933901+00:00' AIRFLOW_CTX_TRY_NUMBER='1' AIRFLOW_CTX_DAG_RUN_ID='manual__2024-06-20T11:42:37.933901+00:00'
[2024-06-20T11:42:41.329+0000] {taskinstance.py:430} INFO - ::endgroup::
[2024-06-20T11:42:41.400+0000] {base.py:84} INFO - Using connection ID 'analytics_localhost' for task execution.
[2024-06-20T11:42:41.423+0000] {taskinstance.py:441} INFO - ::group::Post task execution logs
[2024-06-20T11:42:41.424+0000] {taskinstance.py:2905} ERROR - Task failed with exception
Traceback (most recent call last):
  File "/home/airflow/.local/lib/python3.12/site-packages/airflow/models/taskinstance.py", line 465, in _execute_task
    result = _execute_callable(context=context, **execute_callable_kwargs)
             ^^^^^^^^^^^^^^^^^^^^^^^^^^^^^^^^^^^^^^^^^^^^^^^^^^^^^^^^^^^^^
  File "/home/airflow/.local/lib/python3.12/site-packages/airflow/models/taskinstance.py", line 432, in _execute_callable
    return execute_callable(context=context, **execute_callable_kwargs)
           ^^^^^^^^^^^^^^^^^^^^^^^^^^^^^^^^^^^^^^^^^^^^^^^^^^^^^^^^^^^^
  File "/home/airflow/.local/lib/python3.12/site-packages/airflow/models/baseoperator.py", line 401, in wrapper
    return func(self, *args, **kwargs)
           ^^^^^^^^^^^^^^^^^^^^^^^^^^^
  File "/home/airflow/.local/lib/python3.12/site-packages/airflow/operators/python.py", line 235, in execute
    return_value = self.execute_callable()
                   ^^^^^^^^^^^^^^^^^^^^^^^
  File "/home/airflow/.local/lib/python3.12/site-packages/airflow/operators/python.py", line 252, in execute_callable
    return self.python_callable(*self.op_args, **self.op_kwargs)
           ^^^^^^^^^^^^^^^^^^^^^^^^^^^^^^^^^^^^^^^^^^^^^^^^^^^^^
  File "/opt/airflow/dags/batch-processing_dag.py", line 116, in load_data
    cursor.execute("""
  File "/home/airflow/.local/lib/python3.12/site-packages/MySQLdb/cursors.py", line 179, in execute
    res = self._query(mogrified_query)
          ^^^^^^^^^^^^^^^^^^^^^^^^^^^^
  File "/home/airflow/.local/lib/python3.12/site-packages/MySQLdb/cursors.py", line 330, in _query
    db.query(q)
  File "/home/airflow/.local/lib/python3.12/site-packages/MySQLdb/connections.py", line 261, in query
    _mysql.connection.query(self, query)
MySQLdb.DataError: (1406, "Data too long for column 'description' at row 1")
[2024-06-20T11:42:41.436+0000] {taskinstance.py:1206} INFO - Marking task as FAILED. dag_id=etl_to_analytics_database_v3, task_id=load_data, run_id=manual__2024-06-20T11:42:37.933901+00:00, execution_date=20240620T114237, start_date=20240620T114241, end_date=20240620T114241
[2024-06-20T11:42:41.445+0000] {standard_task_runner.py:110} ERROR - Failed to execute job 802 for task load_data ((1406, "Data too long for column 'description' at row 1"); 18371)
[2024-06-20T11:42:41.494+0000] {local_task_job_runner.py:240} INFO - Task exited with return code 1
[2024-06-20T11:42:41.504+0000] {taskinstance.py:3503} INFO - 0 downstream tasks scheduled from follow-on schedule check
[2024-06-20T11:42:41.506+0000] {local_task_job_runner.py:222} INFO - ::endgroup::
