[2024-06-18T13:11:56.265+0000] {local_task_job_runner.py:120} INFO - ::group::Pre task execution logs
[2024-06-18T13:11:56.282+0000] {taskinstance.py:2076} INFO - Dependencies all met for dep_context=non-requeueable deps ti=<TaskInstance: etl_to_analytics_database_v2.transform_data manual__2024-06-18T13:11:54.251988+00:00 [queued]>
[2024-06-18T13:11:56.289+0000] {taskinstance.py:2076} INFO - Dependencies all met for dep_context=requeueable deps ti=<TaskInstance: etl_to_analytics_database_v2.transform_data manual__2024-06-18T13:11:54.251988+00:00 [queued]>
[2024-06-18T13:11:56.289+0000] {taskinstance.py:2306} INFO - Starting attempt 1 of 1
[2024-06-18T13:11:56.298+0000] {taskinstance.py:2330} INFO - Executing <Task(PythonOperator): transform_data> on 2024-06-18 13:11:54.251988+00:00
[2024-06-18T13:11:56.302+0000] {warnings.py:112} WARNING - /home/***/.local/lib/python3.12/site-packages/***/task/task_runner/standard_task_runner.py:61: DeprecationWarning: This process (pid=6154) is multi-threaded, use of fork() may lead to deadlocks in the child.
  pid = os.fork()

[2024-06-18T13:11:56.304+0000] {standard_task_runner.py:63} INFO - Started process 6155 to run task
[2024-06-18T13:11:56.304+0000] {standard_task_runner.py:90} INFO - Running: ['***', 'tasks', 'run', 'etl_to_analytics_database_v2', 'transform_data', 'manual__2024-06-18T13:11:54.251988+00:00', '--job-id', '742', '--raw', '--subdir', 'DAGS_FOLDER/batch-processing_dag.py', '--cfg-path', '/tmp/tmp3h32kaud']
[2024-06-18T13:11:56.305+0000] {standard_task_runner.py:91} INFO - Job 742: Subtask transform_data
[2024-06-18T13:11:56.334+0000] {task_command.py:426} INFO - Running <TaskInstance: etl_to_analytics_database_v2.transform_data manual__2024-06-18T13:11:54.251988+00:00 [running]> on host 195daacf7793
[2024-06-18T13:11:56.384+0000] {taskinstance.py:2648} INFO - Exporting env vars: AIRFLOW_CTX_DAG_OWNER='***' AIRFLOW_CTX_DAG_ID='etl_to_analytics_database_v2' AIRFLOW_CTX_TASK_ID='transform_data' AIRFLOW_CTX_EXECUTION_DATE='2024-06-18T13:11:54.251988+00:00' AIRFLOW_CTX_TRY_NUMBER='1' AIRFLOW_CTX_DAG_RUN_ID='manual__2024-06-18T13:11:54.251988+00:00'
[2024-06-18T13:11:56.385+0000] {taskinstance.py:430} INFO - ::endgroup::
[2024-06-18T13:11:56.401+0000] {taskinstance.py:441} INFO - ::group::Post task execution logs
[2024-06-18T13:11:56.402+0000] {taskinstance.py:2905} ERROR - Task failed with exception
Traceback (most recent call last):
  File "/home/airflow/.local/lib/python3.12/site-packages/airflow/models/taskinstance.py", line 465, in _execute_task
    result = _execute_callable(context=context, **execute_callable_kwargs)
             ^^^^^^^^^^^^^^^^^^^^^^^^^^^^^^^^^^^^^^^^^^^^^^^^^^^^^^^^^^^^^
  File "/home/airflow/.local/lib/python3.12/site-packages/airflow/models/taskinstance.py", line 432, in _execute_callable
    return execute_callable(context=context, **execute_callable_kwargs)
           ^^^^^^^^^^^^^^^^^^^^^^^^^^^^^^^^^^^^^^^^^^^^^^^^^^^^^^^^^^^^
  File "/home/airflow/.local/lib/python3.12/site-packages/airflow/models/baseoperator.py", line 401, in wrapper
    return func(self, *args, **kwargs)
           ^^^^^^^^^^^^^^^^^^^^^^^^^^^
  File "/home/airflow/.local/lib/python3.12/site-packages/airflow/operators/python.py", line 235, in execute
    return_value = self.execute_callable()
                   ^^^^^^^^^^^^^^^^^^^^^^^
  File "/home/airflow/.local/lib/python3.12/site-packages/airflow/operators/python.py", line 252, in execute_callable
    return self.python_callable(*self.op_args, **self.op_kwargs)
           ^^^^^^^^^^^^^^^^^^^^^^^^^^^^^^^^^^^^^^^^^^^^^^^^^^^^^
  File "/opt/airflow/dags/batch-processing_dag.py", line 46, in transform_data
    dim_users = [{'id': u[0], 'username': u[1], 'role': role_map[u[3]]} for u in users]
                                                        ~~~~~~~~^^^^^^
KeyError: 'weekly'
[2024-06-18T13:11:56.409+0000] {taskinstance.py:1206} INFO - Marking task as FAILED. dag_id=etl_to_analytics_database_v2, task_id=transform_data, run_id=manual__2024-06-18T13:11:54.251988+00:00, execution_date=20240618T131154, start_date=20240618T131156, end_date=20240618T131156
[2024-06-18T13:11:56.417+0000] {standard_task_runner.py:110} ERROR - Failed to execute job 742 for task transform_data ('weekly'; 6155)
[2024-06-18T13:11:56.437+0000] {local_task_job_runner.py:240} INFO - Task exited with return code 1
[2024-06-18T13:11:56.452+0000] {taskinstance.py:3503} INFO - 0 downstream tasks scheduled from follow-on schedule check
[2024-06-18T13:11:56.455+0000] {local_task_job_runner.py:222} INFO - ::endgroup::
