[2024-06-18T13:06:33.224+0000] {local_task_job_runner.py:120} INFO - ::group::Pre task execution logs
[2024-06-18T13:06:33.241+0000] {taskinstance.py:2076} INFO - Dependencies all met for dep_context=non-requeueable deps ti=<TaskInstance: etl_to_analytics_database.transform_data manual__2024-06-18T12:55:09.471576+00:00 [queued]>
[2024-06-18T13:06:33.246+0000] {taskinstance.py:2076} INFO - Dependencies all met for dep_context=requeueable deps ti=<TaskInstance: etl_to_analytics_database.transform_data manual__2024-06-18T12:55:09.471576+00:00 [queued]>
[2024-06-18T13:06:33.246+0000] {taskinstance.py:2306} INFO - Starting attempt 2 of 2
[2024-06-18T13:06:33.255+0000] {taskinstance.py:2330} INFO - Executing <Task(PythonOperator): transform_data> on 2024-06-18 12:55:09.471576+00:00
[2024-06-18T13:06:33.260+0000] {warnings.py:112} WARNING - /home/***/.local/lib/python3.12/site-packages/***/task/task_runner/standard_task_runner.py:61: DeprecationWarning: This process (pid=6065) is multi-threaded, use of fork() may lead to deadlocks in the child.
  pid = os.fork()

[2024-06-18T13:06:33.262+0000] {standard_task_runner.py:63} INFO - Started process 6066 to run task
[2024-06-18T13:06:33.262+0000] {standard_task_runner.py:90} INFO - Running: ['***', 'tasks', 'run', 'etl_to_analytics_database', 'transform_data', 'manual__2024-06-18T12:55:09.471576+00:00', '--job-id', '736', '--raw', '--subdir', 'DAGS_FOLDER/batch-processing_dag.py', '--cfg-path', '/tmp/tmpl7unhtw7']
[2024-06-18T13:06:33.263+0000] {standard_task_runner.py:91} INFO - Job 736: Subtask transform_data
[2024-06-18T13:06:33.301+0000] {task_command.py:426} INFO - Running <TaskInstance: etl_to_analytics_database.transform_data manual__2024-06-18T12:55:09.471576+00:00 [running]> on host 195daacf7793
[2024-06-18T13:06:33.354+0000] {taskinstance.py:2648} INFO - Exporting env vars: AIRFLOW_CTX_DAG_OWNER='***' AIRFLOW_CTX_DAG_ID='etl_to_analytics_database' AIRFLOW_CTX_TASK_ID='transform_data' AIRFLOW_CTX_EXECUTION_DATE='2024-06-18T12:55:09.471576+00:00' AIRFLOW_CTX_TRY_NUMBER='2' AIRFLOW_CTX_DAG_RUN_ID='manual__2024-06-18T12:55:09.471576+00:00'
[2024-06-18T13:06:33.355+0000] {taskinstance.py:430} INFO - ::endgroup::
[2024-06-18T13:06:33.380+0000] {taskinstance.py:441} INFO - ::group::Post task execution logs
[2024-06-18T13:06:33.381+0000] {taskinstance.py:2905} ERROR - Task failed with exception
Traceback (most recent call last):
  File "/home/airflow/.local/lib/python3.12/site-packages/airflow/models/taskinstance.py", line 465, in _execute_task
    result = _execute_callable(context=context, **execute_callable_kwargs)
             ^^^^^^^^^^^^^^^^^^^^^^^^^^^^^^^^^^^^^^^^^^^^^^^^^^^^^^^^^^^^^
  File "/home/airflow/.local/lib/python3.12/site-packages/airflow/models/taskinstance.py", line 432, in _execute_callable
    return execute_callable(context=context, **execute_callable_kwargs)
           ^^^^^^^^^^^^^^^^^^^^^^^^^^^^^^^^^^^^^^^^^^^^^^^^^^^^^^^^^^^^
  File "/home/airflow/.local/lib/python3.12/site-packages/airflow/models/baseoperator.py", line 401, in wrapper
    return func(self, *args, **kwargs)
           ^^^^^^^^^^^^^^^^^^^^^^^^^^^
  File "/home/airflow/.local/lib/python3.12/site-packages/airflow/operators/python.py", line 235, in execute
    return_value = self.execute_callable()
                   ^^^^^^^^^^^^^^^^^^^^^^^
  File "/home/airflow/.local/lib/python3.12/site-packages/airflow/operators/python.py", line 252, in execute_callable
    return self.python_callable(*self.op_args, **self.op_kwargs)
           ^^^^^^^^^^^^^^^^^^^^^^^^^^^^^^^^^^^^^^^^^^^^^^^^^^^^^
  File "/opt/airflow/dags/batch-processing_dag.py", line 38, in transform_data
    users, expenses, incomes, expense_groups, income_groups, roles = kwargs['ti'].xcom_pull(task_ids='extract_data_from_staging')
    ^^^^^^^^^^^^^^^^^^^^^^^^^^^^^^^^^^^^^^^^^^^^^^^^^^^^^^^^^^^^^^
ValueError: not enough values to unpack (expected 6, got 2)
[2024-06-18T13:06:33.396+0000] {taskinstance.py:1206} INFO - Marking task as FAILED. dag_id=etl_to_analytics_database, task_id=transform_data, run_id=manual__2024-06-18T12:55:09.471576+00:00, execution_date=20240618T125509, start_date=20240618T130633, end_date=20240618T130633
[2024-06-18T13:06:33.405+0000] {standard_task_runner.py:110} ERROR - Failed to execute job 736 for task transform_data (not enough values to unpack (expected 6, got 2); 6066)
[2024-06-18T13:06:33.436+0000] {local_task_job_runner.py:240} INFO - Task exited with return code 1
[2024-06-18T13:06:33.453+0000] {taskinstance.py:3503} INFO - 0 downstream tasks scheduled from follow-on schedule check
[2024-06-18T13:06:33.456+0000] {local_task_job_runner.py:222} INFO - ::endgroup::
